Workbook
Name t_973431DD2C61366DBACC56E61E132E05: 'Dropdown Lists'!$C$1:$S$1
Name t_CE9696B61FAB33F2B7AC38BD1A6904FE: 'Dropdown Lists'!$C$2:$D$2
Name t_E596E04876A938D89430E31F12190EAE: 'Dropdown Lists'!$C$3:$D$3
Name t_210AC56516C831C3B975426026564B85: 'Dropdown Lists'!$C$4:$H$4
Name t_5DB35C4529DB3F96BF4F53E1FEC22A97: 'Dropdown Lists'!$C$5:$G$5
Name t_5A2E371F897639048DDE5DABAB9B152C: 'Dropdown Lists'!$C$6:$P$6
Name t_6CC11CB0854138C9A2CAB6DC90AACA9A: 'Dropdown Lists'!$C$7:$L$7
Name t_4BDCEE54E14C361091E3B7E7BC6BFA58: 'Dropdown Lists'!$C$8:$F$8
Name t_4E8EB62C344D3136894C37789B634AC8: 'Dropdown Lists'!$C$9:$K$9
Name t_B0B8A13405AC332B85C28D653BD74B34: 'Dropdown Lists'!$C$10:$H$10
Name t_BA7DD3CAEAAF3F6C820F178068C1218E: 'Dropdown Lists'!$C$11:$S$11
Name t_4D36BB0BF9A633DDA10597E97D2DE70D: 'Dropdown Lists'!$C$12:$G$12
Name t_B8ED491BA39F3348BAC02EDEAF8D3E6A: 'Dropdown Lists'!$C$13:$K$13
Name t_82B46A7862C13CCC82AB8265B43CD5D1: 'Dropdown Lists'!$C$14:$V$14
Name t_102B0F8B23393DE98AFB27DE3D742D48: 'Dropdown Lists'!$C$15:$F$15
Name t_59D4DF059C473EBE9972B0D6D3C6BFD5: 'Dropdown Lists'!$C$16:$E$16
Name t_BCE822F8514631DFAA900D604C1FA3AD: 'Dropdown Lists'!$C$17:$C$17
Name t_4E2BBC766FB4340DA4F274AC6BC0E42A: 'Dropdown Lists'!$C$18:$C$18
Name t_FC32CA4BE4523AFA87DDD9FFB97F7808: 'Dropdown Lists'!$C$19:$H$19
Name t_C085911E85C936C6BD19084938DB0495: 'Dropdown Lists'!$C$20:$T$20
Name t_94660DF92DF63DDEA8BF802328086FC7: 'Dropdown Lists'!$C$21:$T$21
Name t_73E6512CB46F348A83947FB39BCF752F: 'Dropdown Lists'!$C$22:$T$22
Name t_C8870444BCC03E0F81602AC536FFB503: 'Dropdown Lists'!$C$23:$Y$23
Name t_F76924BDB46A359E806CC3D9D6088934: 'Dropdown Lists'!$C$24:$AL$24
Name t_26E3C87B829339BE8536D2D39B5C0888: 'Dropdown Lists'!$C$25:$AA$25
Name t_7EF3CCB8B63637A7A601CBF4D95C11D1: 'Dropdown Lists'!$C$26:$Y$26
Name t_AB465CBD00B53EAB84E00C94A08B5DEA: 'Dropdown Lists'!$C$27:$AL$27
Name t_D3C5568F8E863690832B5922067B68BD: 'Dropdown Lists'!$C$28:$AM$28
Name t_CFCAAD4DFABC30AEAFB900B42A679B7C: 'Dropdown Lists'!$C$29:$Z$29
Name t_DB9F6C5F247E3B5BBFF538B0768DAB78: 'Dropdown Lists'!$C$30:$Y$30
Name t_AA8D9890C22B3144A1B285F31A98A592: 'Dropdown Lists'!$C$31:$AI$31
Name t_1F78D7F4F84730749F0793B28E15DC40: 'Dropdown Lists'!$C$32:$T$32
Name t_164E2C004CFD34F692F316843ED05685: 'Dropdown Lists'!$C$33:$AI$33
Name t_2E9EA565169F3AAFA61C54E852739B92: 'Dropdown Lists'!$C$34:$AM$34
Name t_2F1C8F4BA36D3317B8A60F8F04E34E81: 'Dropdown Lists'!$C$35:$Y$35
Name t_F21A47916C653886B5F7633E0C76CC00: 'Dropdown Lists'!$C$36:$E$36
Name t_DA1B0BA69BFB3BF69586BF4ED975D7AD: 'Dropdown Lists'!$C$37:$E$37
Name t_96B6F55C541D3B82B4149970D9A046FE: 'Dropdown Lists'!$C$38:$R$38
Name t_1A68E0AEE23C30F9BFEF78A191852BDE: 'Dropdown Lists'!$C$39:$R$39
Name t_5EDF549B7C5A3BAC9E1416871DC2FDAF: 'Dropdown Lists'!$C$40:$M$40
Name t_F89DD745747D3D5EB9B38DAB834260A9: 'Dropdown Lists'!$C$41:$M$41
Name t_95B334C7F57D3368AD089F0AE00AD0BA: 'Dropdown Lists'!$C$42:$S$42
Name t_8C5BD9C9DBF23D6D8E539580040DA10C: 'Dropdown Lists'!$C$43:$AH$43
Name t_D497537DA1F13695BD79B47E62B33DA2: 'Dropdown Lists'!$C$44:$R$44
Name t_4D79DF73E5C93EEB8A7925BF6E60384D: 'Dropdown Lists'!$C$45:$AC$45
Name t_4CFE4A5C24343316925FE6F113EAF0DA: 'Dropdown Lists'!$C$46:$R$46
Name t_9C9B8F8D92673BCFA86B74DABFA9D856: 'Dropdown Lists'!$C$47:$M$47
Name t_1DBC9E8133AF3C05946B29B34A4C48D0: 'Dropdown Lists'!$C$48:$M$48
Name t_FB0FDA8FA83B38899957AE743B80676D: 'Dropdown Lists'!$C$49:$AI$49
Name t_10AA201A7F9C369D904AC4FDF2E5F638: 'Dropdown Lists'!$C$50:$AC$50
Name t_E6899D1116443FB6936F2B4F5F9BC1AC: 'Dropdown Lists'!$C$51:$AI$51
Name t_4F97159A8B4D3DD0BD09A071FCD98B18: 'Dropdown Lists'!$C$52:$S$52
Name t_53B44E93E11B304895EDFEA6F3AF1904: 'Dropdown Lists'!$C$53:$J$53
Name t_962B956138A734B78A21651BBEA7EFD1: 'Dropdown Lists'!$C$54:$AH$54
Name t_AF5EFC01161B3C7DB5C210293259F858: 'Dropdown Lists'!$C$55:$M$55
Name t_D675724A16653158972AB5FA2AB7D672: 'Dropdown Lists'!$C$56:$M$56
Name t_1A45D7239F783D2199C0A85AA469EA8B: 'Dropdown Lists'!$C$57:$R$57
Name t_14F0E574DE5F33B8841AA0C3A025C18B: 'Dropdown Lists'!$C$58:$R$58
Name t_0840E90374183A469D364E5B1077E4F9: 'Dropdown Lists'!$C$59:$AD$59
Name t_8B8C178010303A41AB4AE679DA70F99B: 'Dropdown Lists'!$C$60:$AN$60

Sheet Instructions
A1: Using your Template
A2: Print this page
A3: On this page, you'll find the necessary details to generate, verify, and submit your template spreadsheet to Temu. For ease of reference throughout the process, we suggest printing out this page.
A4: Save a version of this file on your hard drive in Excel format. Next, input your product information into the Template tab, adhering to the following instructions.
A6: Image Tab
A7: Refer to the Images tab to familiarize yourself with Temu's guidelines for visual content. Ensure that the images you contribute to Temu align with these specified standards to maintain uniformity and excellence.
A8: It's important that an image is supplied for all products. Upload images by providing the image URL.
A10: Example Tab
A11: Check out the Example tab to view a sample of how to input product details. This is provided just for your guidance. Remember, to prevent the incorporation of incorrect product information into your inventory file, you should not edit your own products directly within the Example sheet.
A13: Template Tab
A14: Navigate to the Template tab to populate it with your listing specifics. When you select a Product Type 1. Recommended software: Due to file compatibility considerations, it is recommended to use Office - Excel to use and edit the template file; 2. Template integrity: Do not modify or delete the sheet names, column headers, or their order in the template file. For cells with dropdown enumerations, select and fill in values from the dropdown list. 3. Units of measurement: the units in the template file are related to the publishing site a. The German, Italian, French, Netherlands, Belgium, and Spanish marketplaces all use the metric system: the length unit is centimeters, the weight unit is grams, and the currency unit is EUR i. The length range is 0.1 cm-9,999.9 cm, with a maximum of 1 decimal point, and will be rounded up; ii. The weight range is 0.1 g-9,999,999.9 g, with a maximum of 1 decimal place, and will be rounded up; iii. The price range is €0.01-€99999999.99, with a maximum of 2 decimal places, and will be rounded up. b. The US marketplace uses the imperial system: the length unit is inches, the weight unit is pounds, and the currency unit is USD i. The length range is 0.1 in-999.9 in, with a maximum of 1 decimal point, and will be rounded up; ii. The weight range is 0.01 lb-9999.99 lb, with a maximum of 2 decimal point, and will be rounded up; iii. The price range is $0.01-$99999999.99, with a maximum of 2 decimal points, and will be rounded up. c. Marketplace in UK is metric: the length unit is centimeters, the weight unit is grams, and the currency unit is GBP i. The length range is 0.1 cm-9,999.9 cm, with a maximum of 1 decimal point, and will be rounded up; ii. The weight range is 0.1 g-9,999,999.9 g, with a maximum of 1 decimal place, and will be rounded up; iii. The price range is £0.01-£99999999.99, with a maximum of 2 decimal places, and will be rounded up. 4. Qualifications and photos: Excel does not currently support uploading qualification documents or photos. For products that require these materials, visit Product Compliance to provide them after submission. 5. Mandatory fields: The Excel file includes built-in formulas. When you select a Category, mandatory fields will be indicated with a red border. Ensure all mandatory fields are correctly filled in. While you are not required to fill in optional fields, it is recommended that you provide as much information as possible for better product performance. 6. Quantity limit: In each file, up to 2000 lines of content are allowed, otherwise products will not be able to be added to the file. 7. Duplicate columns: The Excel file is collapsed by default. You can click on 1 and 2 at the top of the Excel file.
A17: Submit the spreadsheet
... A23: From time to time, Temu will update valid values, data validation rules, explanatory text, and requirements. Please use the latest generated template files.

Sheet Images
A1: Image Standards
A3: Every product on Temu needs one or more product images. Choose images that are clear, straightforward, and easy to understand. They must accurately represent the product and be information-rich and attractively presented. Show only the product that is being offered for sale. Whenever possible, provide several images, with each one showing different angles and details of the product. This is your opportunity to show your product to your customer, so quality matters.
A4: We reserve the right to reject images that do not meet our image standards.
A5: It is your responsibility to ensure that you have all necessary rights to the images you submit.
A7: SKU images
A9: The SKU images will be displayed at the top of the product page. Different SKU images will form a carousel of the product.
A10: For apparel products, the images you upload should be with a maximum size of 3MB, an aspect ratio of 3:4, width ≥ 1340px, height ≥ 1785px. The SKUs with the same color will share a set of carousel images.
A11: For non-apparel products, the images you upload should be with a maximum size of 3MB, an aspect ratio of 1:1, and width and height ≥ 800px.
A12: You can upload up to ten images, with each cell containing one image URL.
A14: Product video
A16: The product video will be displayed at the top of the product page.
A17: The video you upload should be with a maximum size of 100MB, a length not exceeding 180 seconds, and a minimum resolution of 720P.
... A28: Upload the video with a maximum size of 300MB, a length not exceeding 180 seconds, an aspect ratio of either 1:1, 4:3, or 16:9, and a minimum resolution of 720P.

Sheet Example
A1: 1. Besides reviewing the contents of the Example tab, kindly peruse the Instructions tab provided in this document.
A2: 2. Be aware that the examples provided serve merely as illustrations. The columns appearing in your tailored template will vary according to the selected Category. Utilize the Template tab to generate the template spreadsheet.
A3: 3. Some of the optional columns are collapsed for the purpose of better representation. Please show those collapsed areas by clicking '+' button on the corresponding column or section
A4: 4. Errors when you submit a product entry can be resolved by viewing the Processing results, or by contacting Seller Support.
A5: Some fields are Required. Other are Optional. | B5: Product Identity | H5: Product Description | BN5: Product Detail | GT5: Sale Property (At Least One, At Most Two) | HL5: Size Chart | IE5: Variations | IY5: Offer | JC5: Qualifications
B6: Category | C6: Product Name | D6: Contribution Goods | E6: Contribution SKU | F6: Brand | G6: Trademark | H6: Product Description | I6: Bullet Point | J6: Bullet Point | K6: Bullet Point | L6: Bullet Point | M6: Bullet Point | N6: Bullet Point | O6: Detail Images URL | P6: Detail Images URL | Q6: Detail Images URL | R6: Detail Images URL | S6: Detail Images URL | T6: Detail Images URL | U6: Detail Images URL | V6: Detail Images URL | W6: Detail Images URL | X6: Detail Images URL | Y6: Detail Images URL | Z6: Detail Images URL | AA6: Detail Images URL | AB6: Detail Images URL | AC6: Detail Images URL | AD6: Detail Images URL | AE6: Detail Images URL | AF6: Detail Images URL | AG6: Detail Images URL | AH6: Detail Images URL | AI6: Detail Images URL | AJ6: Detail Images URL | AK6: Detail Images URL | AL6: Detail Images URL | AM6: Detail Images URL | AN6: Detail Images URL | AO6: Detail Images URL | AP6: Detail Images URL | AQ6: Detail Images URL | AR6: Detail Images URL | AS6: Detail Images URL | AT6: Detail Images URL | AU6: Detail Images URL | AV6: Detail Images URL | AW6: Detail Images URL | AX6: Detail Images URL | AY6: Detail Images URL | AZ6: Detail Images URL | BA6: Detail Images URL | BB6: Detail Images URL | BC6: Detail Images URL | BD6: Detail Images URL | BE6: Detail Images URL | BF6: Detail Images URL | BG6: Detail Images URL | BH6: Detail Images URL | BI6: Detail Images URL | BJ6: Detail Images URL | BK6: Detail Images URL | BL6: Detail Images URL | BM6: Detail Video URL | BN6: 4115 - Shelf Life - value | BO6: 4115 - Shelf Life - unit | BP6: 4118 - Speciality | BQ6: 4118 - Speciality | BR6: 4118 - Speciality | BS6: 4119 - Item Weight - value | BT6: 4119 - Item Weight - unit | BU6: 4120 - Package Weight - value | BV6: 4120 - Package Weight - unit | BW6: 4121 - Allergen Information | BX6: 4121 - Allergen Information | BY6: 4121 - Allergen Information | BZ6: 4121 - Allergen Information | CA6: 4121 - Allergen Information | CB6: 4121 - Allergen Information | CC6: 4121 - Allergen Information | CD6: 4121 - Allergen Information | CE6: 4121 - Allergen Information | CF6: 4121 - Allergen Information | CG6: 195 - Diet Type | CH6: 195 - Diet Type | CI6: 195 - Diet Type | CJ6: 6160 - Brand Name | CK6: 6210 - USDA certified | CL6: 4110 - Production Date | CM6: 6440 - best before | CN6: 361 - Package Quantity | CO6: 12 - Material | CP6: 12 - Material | CQ6: 12 - Material | CR6: 12 - Material | CS6: 12 - Material | CT6: 4134 - Publisher | CU6: 4130 - Country/Region Of Origin | CV6: 4137 - Author | CW6: 1120 - Set or not | CX6: 4133 - Binding Type | CY6: 4123 - Languages | CZ6: 4123 - Languages | DA6: 4123 - Languages | DB6: 4142 - Year Of Publication | DC6: 4124 - Number Of Pages (pages) - value | DD6: 4124 - Number Of Pages (pages) - unit | DE6: 4131 - Number Of Words (10,000 Words) | DF6: 4127 - Product Weight (g) - value | DG6: 4127 - Product Weight (g) - unit | DH6: 4128 - Maximum Reading Age (years) - value | DI6: 4128 - Maximum Reading Age (years) - unit | DJ6: 4129 - Minimum Reading Age (years) - value | DK6: 4129 - Minimum Reading Age (years) - unit | DL6: 121 - Material | DM6: 121 - Material | DN6: 121 - Material | DO6: 121 - Material | DP6: 121 - Material | DQ6: 132 - Finish Type | DR6: 210 - Furniture Finish | DS6: 19 - Style | DT6: 1561 - Power Supply | DU6: 1132 - Operating Voltage | DV6: 1485 - Plug Type | DW6: 1485 - Plug Type | DX6: 1485 - Plug Type | DY6: 1571 - Acceptable Voltage Range | DZ6: 4102 - Contain Wooden Materials | EA6: 4097 - Tree Species | EB6: 4097 - Tree Species | EC6: 4098 - Wood Formation Type | ED6: 4098 - Wood Formation Type | EE6: 4098 - Wood Formation Type | EF6: 4099 - Fiberboard Density | EG6: 6171 - Wether Independent | EH6: 6172 - Closed Storage Capacity | EI6: 6173 - Height After Assembly | EJ6: 6174 - Physical Weight | EK6: 2153 - Battery Properties | EL6: 2147 - Rechargeable Battery | EM6: 2154 - Solar Battery Type | EN6: 3740 - Non-rechargeable Battery | EO6: 2028 - Battery Capacity (mAh) - value | EP6: 2028 - Battery Capacity (mAh) - unit | EQ6: 63 - Color | ER6: 15 - Composition:Nylon | ES6: 15 - Composition:Polyester | ET6: 15 - Composition:Polyamide | EU6: 15 - Composition:Elastane | EV6: 15 - Composition:Spandex | EW6: 15 - Composition:Acrylic | EX6: 15 - Composition:Cotton | EY6: 15 - Composition:Silk | EZ6: 15 - Composition:Linen | FA6: 15 - Composition:Modal | FB6: 15 - Composition:Viscose | FC6: 15 - Composition:Rayon | FD6: 15 - Composition:Carbon | FE6: 15 - Composition:Metal | FF6: 15 - Composition:Wool | FG6: 15 - Composition:Cashmere | FH6: 15 - Composition:Mohair | FI6: 15 - Composition:Rabbit Hair | FJ6: 15 - Composition:Bovine Leather | FK6: 15 - Composition:Sheep Leather | FL6: 15 - Composition:Pig Leather | FM6: 15 - Composition:Polyurethane | FN6: 15 - Composition:Polyvinyl Chloride | FO6: 15 - Composition:Cupro | FP6: 15 - Composition:Lyocell | FQ6: 15 - Composition:Acetate | FR6: 15 - Composition:Down | FS6: 15 - Composition:Feather | FT6: 15 - Composition:Duck Down | FU6: 15 - Composition:Alpaca | FV6: 15 - Composition:Metallized Fibres | FW6: 15 - Composition:Polypropylene fibers | FX6: 15 - Composition:Other Fibers | FY6: 28 - Length | FZ6: 74 - Belt | GA6: 29 - Sleeve Length | GB6: 27 - Sleeve Type | GC6: 94 - Chest Pad | GD6: 83 - Details | GE6: 26 - Pattern | GF6: 24 - Sheer | GG6: 22 - Fabric | GH6: 86 - Placket Type | GI6: 78 - Lining | GJ6: 113 - Contour | GK6: 76 - Season | GL6: 20 - Operation Instruction | GM6: 114 - Fit Type | GN6: 1352 - Fabric Elasticity | GO6: 1919 - Printing Type | GP6: 2103 - Style source | GQ6: 1192 - Weaving Method | GR6: 21 - Collar Style | GS6: 6227 - Collection | GT6: Variation Theme | GU6: Size Family | GV6: Sub-Size Family | GW6: Size | GX6: Color | GY6: Color | GZ6: Size | HA6: Style | HB6: Material | HC6: Flavors | HD6: Applicable People | HE6: Capacity | HF6: Composition | HG6: Weight | HH6: Items | HI6: Quantity | HJ6: Model | HK6: Hair Length | HL6: Unit | HM6: US Size | HN6: Tops - Product - Shoulder width | HO6: Tops - Product - Bust size | HP6: Tops - Product - Clothes length | HQ6: Tops - Product - Sleeve length | HR6: Tops - Product - Waist size | HS6: Tops - Product - Underbust | HT6: Tops - Product - Neck | HU6: Tops - Product - Hem | HV6: Tops - Product - Cuffs | HW6: Tops - Body - Bust - min | HX6: Tops - Body - Bust - max | HY6: Tops - Body - Waist - min | HZ6: Tops - Body - Waist - max | IA6: Tops - Body - Hips - min | IB6: Tops - Body - Hips - max | IC6: Tops - Body - Height - min | ID6: Tops - Body - Height - max | IE6: SKU Images URL | IF6: SKU Images URL | IG6: SKU Images URL | IH6: SKU Images URL | II6: SKU Images URL | IJ6: SKU Images URL | IK6: SKU Images URL | IL6: SKU Images URL | IM6: SKU Images URL | IN6: SKU Images URL | IO6: Quantity | IP6: Base Price - EUP | IQ6: List Price - EUP | IR6: Not available for List price | IS6: Weight - g | IT6: Length - cm | IU6: Width - cm | IV6: Height - cm | IW6: External Product ID Type | IX6: External Product ID | IY6: Handling Time | IZ6: Shipping Template | JA6: Import Designation | JB6: Item Tax Code | JC6: Product Guide
A7: Example 1: This is an example of providing a new listing. This example has no variation and is listed as a single detail page. | B7: 29069 | C7: Example Women T-shirt, 156 Black T-shirt | D7: EXAMPLE-156-US-Black-one-size | E7: EXAMPLE-156-US-Black-one-size | H7: Unleash your personal style with our classic fit tee. Crafted from 100% cotton, it offers unmatched comfort and durability. The tee features a unique, eye-catching graphic that embodies modern chic. Perfect for casual outings or layering under a jacket, this T-shirt is versatile for any occasion. With a breathable fabric that holds its shape, it's a wardrobe staple you'll reach for time and again. Make a statement and stay cozy in a shirt designed to express who you are. (Character count: 493) | I7: 100% premium cotton for ultimate comfort. | J7: Timeless design meets modern style. | K7: Durable fabric, perfect for daily wear | L7: Machine washable and easy to care for. | M7: Versatile fit for every body type. | O7: http://www.companyname.com/images/1250.main.jpg | P7: http://www.companyname.com/images/1250.main.jpg | Q7: http://www.companyname.com/images/1250.main.jpg | R7: http://www.companyname.com/images/1250.main.jpg | CO7: Recycle Polyester | DS7: Y2K | ER7: 32 | ES7: 28 | ET7: 40 | FY7: Short Length | FZ7: Yes | GA7: Long Sleeve | GB7: Raglan sleeve | GC7: No Padding | GD7: Fake Pockets | GE7: Mushroom | GF7: No | GG7: Non-Stretch | GH7: Half Placket | GI7: Cashmere | GJ7: H | GK7: Fall | GL7: Do not wash | GM7: Regular | GN7: No Elasticity | GO7: Positioning Printing | GP7: Buyer provides | GQ7: Woven | GR7: Off the Shoulder | GS7: Middle East | GT7: Size × Color | GU7: US/EU size | GV7: One Size | GW7: one-size | GX7: Black | HL7: cm | HM7: one-size | HO7: 36 | HP7: 28 | HW7: 33.9 | HX7: 35.5 | HY7: 26 | HZ7: 27.6 | IA7: 35.9 | IB7: 37.4 | IE7: http://www.companyname.com/images/1250.main.jpg | IF7: http://www.companyname.com/images/1250.main.jpg | IG7: http://www.companyname.com/images/1250.main.jpg | IO7: 5 | IP7: 2.99 | IQ7: 5.99 | IS7: 9.2 | IT7: 2 | IU7: 3 | IV7: 4 | IY7: 1 Day | IZ7: test1 | JA7: Imported | JB7: GEN STANDARD
B8: 12408 | C8: Example reclaimed Cabinet Solid Wood with 4 Drawers | D8: EXAMPLE-576-Brown | E8: EXAMPLE-576-Brown | DL8: Wood | DQ8: Painted | DR8: Cedar | DS8: Vintage | DT8: Plug Powered | DU8: 110V (included)-240V (included) | DV8: US Plug | DZ8: Yes | EA8: Hardwood | EC8: Block Board (large Core Board) | EG8: Yes | EH8: <3.2 Cubic Feet | EI8: <27 Inches | EJ8: <30 Lbs | EK8: Without Battery | EQ8: Red | GT8: Color × Style | GY8: Red | HA8: Vintage | IE8: http://www.companyname.com/images/1250.main.jpg | IF8: http://www.companyname.com/images/1250.main.jpg | IG8: http://www.companyname.com/images/1250.main.jpg | IO8: 0 | IP8: 2.99 | IQ8: 5.99 | IS8: 9.2 | IT8: 2 | IU8: 3 | IV8: 4 | IY8: 1 Day | IZ8: test1 | JA8: Imported | JB8: GEN STANDARD | JC8: http://www.companyname.com/images/productguide.pdf
B9: 44936 | C9: Example book for US with isbn | D9: EXAMPLEISBN9787040205190 | E9: EXAMPLEISBN9787040205190 | CT9: Example publisher | CU9: USA | CV9: Example author | CW9: No | CX9: Paperback | CY9: English | DB9: 44604 | DC9: 300 | DD9: Page | DE9: 1000 | DF9: 200 | DG9: g | DH9: 99 | DI9: years old | DJ9: 1 | DK9: years old | GT9: Items | HH9: Example book for US with isbn | IE9: http://www.companyname.com/images/1250.main.jpg | IF9: http://www.companyname.com/images/1250.main.jpg | IG9: http://www.companyname.com/images/1250.main.jpg | IO9: 20 | IP9: 7.82 | IQ9: 10.23 | IS9: 9.2 | IT9: 2 | IU9: 3 | IV9: 4 | IW9: ISBN | IX9: 920000021 | IY9: 1 Day | IZ9: test1 | JA9: Imported | JB9: BOOKS GEN
B10: 42550 | C10: Example food Potato Chips Pack of 6 - 80g per bag | D10: EXAMPLE-Pack6 - 80g | E10: EXAMPLE-Pack6 - 80g | BN10: 30 | BO10: Day | BP10: Wild-Caught | BQ10: Certified-Humane-Raised-And-Handled | BS10: 90 | BT10: g | BU10: 106 | BV10: g | BW10: Contains cow's milk | BX10: Contains Peanuts | CG10: Plant Based | CJ10: Example brand name | CK10: less than 70% organic ingredients | CL10: 45550 | CM10: 45641 | GT10: Weight | HG10: 90g | IE10: http://www.companyname.com/images/1250.main.jpg | IF10: http://www.companyname.com/images/1250.main.jpg | IG10: http://www.companyname.com/images/1250.main.jpg | IO10: 20 | IP10: 5.39 | IR10: N/A | IS10: 9.2 | IT10: 2 | IU10: 3 | IV10: 4 | IY10: 1 Day | IZ10: test1 | JA10: Imported | JB10: FOOD GEN
A12: Example 2: This is an example of a product with 1 variation theme (i.e., size) with 3 variations. These are 3 "Child" SKUs in a "Parent" Goods. Note: For product-level information such as Product Name, Product Description, Product Detail, Offer, Qualifications, please ensure that each line is filled out correctly and the information is consistently entered. | B12: 29069 | C12: Example Women T-shirt, 156 Black T-shirt | D12: EXAMPLE-156-US-Black | E12: EXAMPLE-156-US-Black-S | H12: Unleash your personal style with our classic fit tee. Crafted from 100% cotton, it offers unmatched comfort and durability. The tee features a unique, eye-catching graphic that embodies modern chic. Perfect for casual outings or layering under a jacket, this T-shirt is versatile for any occasion. With a breathable fabric that holds its shape, it's a wardrobe staple you'll reach for time and again. Make a statement and stay cozy in a shirt designed to express who you are. (Character count: 493) | I12: 100% premium cotton for ultimate comfort. | J12: Timeless design meets modern style. | K12: Durable fabric, perfect for daily wear | L12: Machine washable and easy to care for. | M12: Versatile fit for every body type. | O12: http://www.companyname.com/images/1250.main.jpg | P12: http://www.companyname.com/images/1250.main.jpg | Q12: http://www.companyname.com/images/1250.main.jpg | R12: http://www.companyname.com/images/1250.main.jpg | CO12: Recycle Polyester | DS12: Y2K | ER12: 32 | ES12: 28 | ET12: 40 | FY12: Short Length | FZ12: Yes | GA12: Long Sleeve | GB12: Raglan sleeve | GC12: No Padding | GD12: Fake Pockets | GE12: Mushroom | GF12: No | GG12: Non-Stretch | GH12: Half Placket | GI12: Cashmere | GJ12: H | GK12: Fall | GL12: Do not wash | GM12: Regular | GN12: No Elasticity | GO12: Positioning Printing | GP12: Buyer provides | GQ12: Woven | GR12: Off the Shoulder | GS12: Middle East | GT12: Size × Color | GU12: US/EU size | GV12: Alpha | GW12: S | GX12: Black | HL12: cm | HM12: 0 | HO12: 36 | HP12: 28 | HW12: 33.9 | HX12: 35.5 | HY12: 26 | HZ12: 27.6 | IA12: 35.9 | IB12: 37.4 | IE12: http://www.companyname.com/images/1250.main.jpg | IF12: http://www.companyname.com/images/1250.main.jpg | IG12: http://www.companyname.com/images/1250.main.jpg | IO12: 5 | IP12: 2.99 | IQ12: 5.99 | IS12: 9.2 | IT12: 2 | IU12: 3 | IV12: 4 | IY12: 1 Day | IZ12: test1 | JA12: Imported | JB12: GEN STANDARD
B13: 29069 | C13: Example Women T-shirt, 156 Black T-shirt | D13: EXAMPLE-156-US-Black | E13: EXAMPLE-156-US-Black-M | H13: Unleash your personal style with our classic fit tee. Crafted from 100% cotton, it offers unmatched comfort and durability. The tee features a unique, eye-catching graphic that embodies modern chic. Perfect for casual outings or layering under a jacket, this T-shirt is versatile for any occasion. With a breathable fabric that holds its shape, it's a wardrobe staple you'll reach for time and again. Make a statement and stay cozy in a shirt designed to express who you are. (Character count: 493) | I13: 100% premium cotton for ultimate comfort. | J13: Timeless design meets modern style. | K13: Durable fabric, perfect for daily wear | L13: Machine washable and easy to care for. | M13: Versatile fit for every body type. | O13: http://www.companyname.com/images/1250.main.jpg | P13: http://www.companyname.com/images/1250.main.jpg | Q13: http://www.companyname.com/images/1250.main.jpg | R13: http://www.companyname.com/images/1250.main.jpg | CO13: Recycle Polyester | DS13: Y2K | ER13: 32 | ES13: 28 | ET13: 40 | FY13: Short Length | FZ13: Yes | GA13: Long Sleeve | GB13: Raglan sleeve | GC13: No Padding | GD13: Fake Pockets | GE13: Mushroom | GF13: No | GG13: Non-Stretch | GH13: Half Placket | GI13: Cashmere | GJ13: H | GK13: Fall | GL13: Do not wash | GM13: Regular | GN13: No Elasticity | GO13: Positioning Printing | GP13: Buyer provides | GQ13: Woven | GR13: Off the Shoulder | GS13: Middle East | GT13: Size × Color | GU13: US/EU size | GV13: Alpha | GW13: M | GX13: Black | HL13: cm | HM13: 2 | HO13: 40 | HP13: 29 | HW13: 35.5 | HX13: 37 | HY13: 27.6 | HZ13: 29.2 | IA13: 27.4 | IB13: 39 | IE13: http://www.companyname.com/images/1250.main.jpg | IF13: http://www.companyname.com/images/1250.main.jpg | IG13: http://www.companyname.com/images/1250.main.jpg | IO13: 5 | IP13: 2.99 | IQ13: 5.99 | IS13: 9.2 | IT13: 2 | IU13: 3 | IV13: 4 | IY13: 1 Day | IZ13: test1 | JA13: Imported | JB13: GEN STANDARD
B14: 29069 | C14: Example Women T-shirt, 156 Black T-shirt | D14: EXAMPLE-156-US-Black | E14: EXAMPLE-156-US-Black-L | H14: Unleash your personal style with our classic fit tee. Crafted from 100% cotton, it offers unmatched comfort and durability. The tee features a unique, eye-catching graphic that embodies modern chic. Perfect for casual outings or layering under a jacket, this T-shirt is versatile for any occasion. With a breathable fabric that holds its shape, it's a wardrobe staple you'll reach for time and again. Make a statement and stay cozy in a shirt designed to express who you are. (Character count: 493) | I14: 100% premium cotton for ultimate comfort. | J14: Timeless design meets modern style. | K14: Durable fabric, perfect for daily wear | L14: Machine washable and easy to care for. | M14: Versatile fit for every body type. | O14: http://www.companyname.com/images/1250.main.jpg | P14: http://www.companyname.com/images/1250.main.jpg | Q14: http://www.companyname.com/images/1250.main.jpg | R14: http://www.companyname.com/images/1250.main.jpg | CO14: Recycle Polyester | DS14: Y2K | ER14: 32 | ES14: 28 | ET14: 40 | FY14: Short Length | FZ14: Yes | GA14: Long Sleeve | GB14: Raglan sleeve | GC14: No Padding | GD14: Fake Pockets | GE14: Mushroom | GF14: No | GG14: Non-Stretch | GH14: Half Placket | GI14: Cashmere | GJ14: H | GK14: Fall | GL14: Do not wash | GM14: Regular | GN14: No Elasticity | GO14: Positioning Printing | GP14: Buyer provides | GQ14: Woven | GR14: Off the Shoulder | GS14: Middle East | GT14: Size × Color | GU14: US/EU size | GV14: Alpha | GW14: L | GX14: Black | HL14: cm | HM14: 4 | HO14: 44 | HP14: 30 | HW14: 37.4 | HX14: 39.8 | HY14: 29.6 | HZ14: 31.9 | IA14: 39.4 | IB14: 41.8 | IE14: http://www.companyname.com/images/1250.main.jpg | IF14: http://www.companyname.com/images/1250.main.jpg | IG14: http://www.companyname.com/images/1250.main.jpg | IO14: 5 | IP14: 2.99 | IQ14: 5.99 | IS14: 9.2 | IT14: 2 | IU14: 3 | IV14: 4 | IY14: 1 Day | IZ14: test1 | JA14: Imported | JB14: GEN STANDARD
B15: 12408 | C15: Example reclaimed Cabinet Solid Wood with 4 Drawers | D15: EXAMPLE-576 | E15: EXAMPLE-576-Brown | DL15: Wood | DQ15: Painted | DR15: Cedar | DS15: Vintage | DT15: Plug Powered | DU15: 110V (included)-240V (included) | DV15: US Plug | DZ15: Yes | EA15: Hardwood | EC15: Block Board (large Core Board) | EG15: Yes | EH15: <3.2 Cubic Feet | EI15: <27 Inches | EJ15: <30 Lbs | EK15: Without Battery | EQ15: Red | GT15: Color | GY15: Brown | IE15: http://www.companyname.com/images/1250.main.jpg | IF15: http://www.companyname.com/images/1250.main.jpg | IG15: http://www.companyname.com/images/1250.main.jpg | IO15: 5 | IP15: 2.99 | IQ15: 5.99 | IS15: 9.2 | IT15: 2 | IU15: 3 | IV15: 4 | IY15: 1 Day | IZ15: test1 | JA15: Imported | JB15: GEN STANDARD
B16: 12408 | C16: Example reclaimed Cabinet Solid Wood with 4 Drawers | D16: EXAMPLE-576 | E16: EXAMPLE-576-white | DL16: Wood | DQ16: Painted | DR16: Cedar | DS16: Vintage | DT16: Plug Powered | DU16: 110V (included)-240V (included) | DV16: US Plug | DZ16: Yes | EA16: Hardwood | EC16: Block Board (large Core Board) | EG16: Yes | EH16: <3.2 Cubic Feet | EI16: <27 Inches | EJ16: <30 Lbs | EK16: Without Battery | EQ16: Red | GT16: Color | GY16: white | IE16: http://www.companyname.com/images/1250.main.jpg | IF16: http://www.companyname.com/images/1250.main.jpg | IG16: http://www.companyname.com/images/1250.main.jpg | IO16: 5 | IP16: 2.99 | IQ16: 5.99 | IS16: 9.2 | IT16: 2 | IU16: 3 | IV16: 4 | IY16: 1 Day | IZ16: test1 | JA16: Imported | JB16: GEN STANDARD
B17: 12408 | C17: Example reclaimed Cabinet Solid Wood with 4 Drawers | D17: EXAMPLE-576 | E17: EXAMPLE-576-red | DL17: Wood | DQ17: Painted | DR17: Cedar | DS17: Vintage | DT17: Plug Powered | DU17: 110V (included)-240V (included) | DV17: US Plug | DZ17: Yes | EA17: Hardwood | EC17: Block Board (large Core Board) | EG17: Yes | EH17: <3.2 Cubic Feet | EI17: <27 Inches | EJ17: <30 Lbs | EK17: Without Battery | EQ17: Red | GT17: Color | GY17: red | IE17: http://www.companyname.com/images/1250.main.jpg | IF17: http://www.companyname.com/images/1250.main.jpg | IG17: http://www.companyname.com/images/1250.main.jpg | IO17: 5 | IP17: 2.99 | IQ17: 5.99 | IS17: 9.2 | IT17: 2 | IU17: 3 | IV17: 4 | IY17: 1 Day | IZ17: test1 | JA17: Imported | JB17: GEN STANDARD
A19: Example 3: This is an example of a product with 2 variation themes (i.e., size and color) with 4 variations. These are 4 "Child" SKUs in a "Parent" Goods. Note: For product-level information such as Product Name, Product Description, Product Detail, Offer, Qualifications, please ensure that each line is filled out correctly and the information is consistently entered. | B19: 29069 | C19: Example Women T-shirt, 156 Black T-shirt | D19: EXAMPLE-156-US | E19: EXAMPLE-156-US-Black-S | H19: Unleash your personal style with our classic fit tee. Crafted from 100% cotton, it offers unmatched comfort and durability. The tee features a unique, eye-catching graphic that embodies modern chic. Perfect for casual outings or layering under a jacket, this T-shirt is versatile for any occasion. With a breathable fabric that holds its shape, it's a wardrobe staple you'll reach for time and again. Make a statement and stay cozy in a shirt designed to express who you are. (Character count: 493) | I19: 100% premium cotton for ultimate comfort. | J19: Timeless design meets modern style. | K19: Durable fabric, perfect for daily wear | L19: Machine washable and easy to care for. | M19: Versatile fit for every body type. | O19: http://www.companyname.com/images/1250.main.jpg | P19: http://www.companyname.com/images/1250.main.jpg | Q19: http://www.companyname.com/images/1250.main.jpg | R19: http://www.companyname.com/images/1250.main.jpg | CO19: Recycle Polyester | DS19: Y2K | ER19: 32 | ES19: 28 | ET19: 40 | FY19: Short Length | FZ19: Yes | GA19: Long Sleeve | GB19: Raglan sleeve | GC19: No Padding | GD19: Fake Pockets | GE19: Mushroom | GF19: No | GG19: Non-Stretch | GH19: Half Placket | GI19: Cashmere | GJ19: H | GK19: Fall | GL19: Do not wash | GM19: Regular | GN19: No Elasticity | GO19: Positioning Printing | GP19: Buyer provides | GQ19: Woven | GR19: Off the Shoulder | GS19: Middle East | GT19: Size × Color | GU19: US/EU size | GV19: Alpha | GW19: S | GX19: Black | HL19: cm | HM19: 0 | HO19: 36 | HP19: 28 | HW19: 33.9 | HX19: 35.5 | HY19: 26 | HZ19: 27.6 | IA19: 35.9 | IB19: 37.4 | IE19: http://www.companyname.com/images/1250.main.jpg | IF19: http://www.companyname.com/images/1250.main.jpg | IG19: http://www.companyname.com/images/1250.main.jpg | IO19: 5 | IP19: 2.99 | IQ19: 5.99 | IS19: 9.2 | IT19: 2 | IU19: 3 | IV19: 4 | IY19: 1 Day | IZ19: test1 | JA19: Imported | JB19: GEN STANDARD
B20: 29069 | C20: Example Women T-shirt, 156 Black T-shirt | D20: EXAMPLE-156-US | E20: EXAMPLE-156-US-Black-M | H20: Unleash your personal style with our classic fit tee. Crafted from 100% cotton, it offers unmatched comfort and durability. The tee features a unique, eye-catching graphic that embodies modern chic. Perfect for casual outings or layering under a jacket, this T-shirt is versatile for any occasion. With a breathable fabric that holds its shape, it's a wardrobe staple you'll reach for time and again. Make a statement and stay cozy in a shirt designed to express who you are. (Character count: 493) | I20: 100% premium cotton for ultimate comfort. | J20: Timeless design meets modern style. | K20: Durable fabric, perfect for daily wear | L20: Machine washable and easy to care for. | M20: Versatile fit for every body type. | O20: http://www.companyname.com/images/1250.main.jpg | P20: http://www.companyname.com/images/1250.main.jpg | Q20: http://www.companyname.com/images/1250.main.jpg | R20: http://www.companyname.com/images/1250.main.jpg | CO20: Recycle Polyester | DS20: Y2K | ER20: 32 | ES20: 28 | ET20: 40 | FY20: Short Length | FZ20: Yes | GA20: Long Sleeve | GB20: Raglan sleeve | GC20: No Padding | GD20: Fake Pockets | GE20: Mushroom | GF20: No | GG20: Non-Stretch | GH20: Half Placket | GI20: Cashmere | GJ20: H | GK20: Fall | GL20: Do not wash | GM20: Regular | GN20: No Elasticity | GO20: Positioning Printing | GP20: Buyer provides | GQ20: Woven | GR20: Off the Shoulder | GS20: Middle East | GT20: Size × Color | GU20: US/EU size | GV20: Alpha | GW20: M | GX20: Black | HL20: cm | HM20: 2 | HO20: 40 | HP20: 29 | HW20: 35.5 | HX20: 37 | HY20: 27.6 | HZ20: 29.2 | IA20: 27.4 | IB20: 39 | IE20: http://www.companyname.com/images/1250.main.jpg | IF20: http://www.companyname.com/images/1250.main.jpg | IG20: http://www.companyname.com/images/1250.main.jpg | IO20: 5 | IP20: 2.99 | IQ20: 5.99 | IS20: 9.2 | IT20: 2 | IU20: 3 | IV20: 4 | IY20: 1 Day | IZ20: test1 | JA20: Imported | JB20: GEN STANDARD
B21: 29069 | C21: Example Women T-shirt, 156 Black T-shirt | D21: EXAMPLE-156-US | E21: EXAMPLE-156-US-red-S | H21: Unleash your personal style with our classic fit tee. Crafted from 100% cotton, it offers unmatched comfort and durability. The tee features a unique, eye-catching graphic that embodies modern chic. Perfect for casual outings or layering under a jacket, this T-shirt is versatile for any occasion. With a breathable fabric that holds its shape, it's a wardrobe staple you'll reach for time and again. Make a statement and stay cozy in a shirt designed to express who you are. (Character count: 493) | I21: 100% premium cotton for ultimate comfort. | J21: Timeless design meets modern style. | K21: Durable fabric, perfect for daily wear | L21: Machine washable and easy to care for. | M21: Versatile fit for every body type. | O21: http://www.companyname.com/images/1250.main.jpg | P21: http://www.companyname.com/images/1250.main.jpg | Q21: http://www.companyname.com/images/1250.main.jpg | R21: http://www.companyname.com/images/1250.main.jpg | CO21: Recycle Polyester | DS21: Y2K | ER21: 32 | ES21: 28 | ET21: 40 | FY21: Short Length | FZ21: Yes | GA21: Long Sleeve | GB21: Raglan sleeve | GC21: No Padding | GD21: Fake Pockets | GE21: Mushroom | GF21: No | GG21: Non-Stretch | GH21: Half Placket | GI21: Cashmere | GJ21: H | GK21: Fall | GL21: Do not wash | GM21: Regular | GN21: No Elasticity | GO21: Positioning Printing | GP21: Buyer provides | GQ21: Woven | GR21: Off the Shoulder | GS21: Middle East | GT21: Size × Color | GU21: US/EU size | GV21: Alpha | GW21: S | GX21: Red | HL21: cm | HM21: 0 | HO21: 36 | HP21: 28 | HW21: 33.9 | HX21: 35.5 | HY21: 26 | HZ21: 27.6 | IA21: 35.9 | IB21: 37.4 | IE21: http://www.companyname.com/images/1250.main.jpg | IF21: http://www.companyname.com/images/1250.main.jpg | IG21: http://www.companyname.com/images/1250.main.jpg | IO21: 5 | IP21: 3.99 | IQ21: 7.99 | IS21: 9.2 | IT21: 2 | IU21: 3 | IV21: 4 | IY21: 1 Day | IZ21: test1 | JA21: Imported | JB21: GEN STANDARD
B22: 29069 | C22: Example Women T-shirt, 156 Black T-shirt | D22: EXAMPLE-156-US | E22: EXAMPLE-156-US-red-M | H22: Unleash your personal style with our classic fit tee. Crafted from 100% cotton, it offers unmatched comfort and durability. The tee features a unique, eye-catching graphic that embodies modern chic. Perfect for casual outings or layering under a jacket, this T-shirt is versatile for any occasion. With a breathable fabric that holds its shape, it's a wardrobe staple you'll reach for time and again. Make a statement and stay cozy in a shirt designed to express who you are. (Character count: 493) | I22: 100% premium cotton for ultimate comfort. | J22: Timeless design meets modern style. | K22: Durable fabric, perfect for daily wear | L22: Machine washable and easy to care for. | M22: Versatile fit for every body type. | O22: http://www.companyname.com/images/1250.main.jpg | P22: http://www.companyname.com/images/1250.main.jpg | Q22: http://www.companyname.com/images/1250.main.jpg | R22: http://www.companyname.com/images/1250.main.jpg | CO22: Recycle Polyester | DS22: Y2K | ER22: 32 | ES22: 28 | ET22: 40 | FY22: Short Length | FZ22: Yes | GA22: Long Sleeve | GB22: Raglan sleeve | GC22: No Padding | GD22: Fake Pockets | GE22: Mushroom | GF22: No | GG22: Non-Stretch | GH22: Half Placket | GI22: Cashmere | GJ22: H | GK22: Fall | GL22: Do not wash | GM22: Regular | GN22: No Elasticity | GO22: Positioning Printing | GP22: Buyer provides | GQ22: Woven | GR22: Off the Shoulder | GS22: Middle East | GT22: Size × Color | GU22: US/EU size | GV22: Alpha | GW22: M | GX22: Red | HL22: cm | HM22: 2 | HO22: 40 | HP22: 29 | HW22: 35.5 | HX22: 37 | HY22: 27.6 | HZ22: 29.2 | IA22: 27.4 | IB22: 39 | IE22: http://www.companyname.com/images/1250.main.jpg | IF22: http://www.companyname.com/images/1250.main.jpg | IG22: http://www.companyname.com/images/1250.main.jpg | IO22: 5 | IP22: 3.99 | IQ22: 7.99 | IS22: 9.2 | IT22: 2 | IU22: 3 | IV22: 4 | IY22: 1 Day | IZ22: test1 | JA22: Imported | JB22: GEN STANDARD
B23: 12408 | C23: Example reclaimed Cabinet Solid Wood with 4 Drawers | D23: EXAMPLE-576 | E23: Example_Brand Night Stand with 4 Drawers (White, 21 inch) | DL23: Wood | DQ23: Painted | DR23: Cedar | DS23: Vintage | DT23: Plug Powered | DU23: 110V (included)-240V (included) | DV23: US Plug | DZ23: Yes | EA23: Hardwood | EC23: Block Board (large Core Board) | EG23: Yes | EH23: <3.2 Cubic Feet | EI23: <27 Inches | EJ23: <30 Lbs | EK23: Without Battery | EQ23: Red | GT23: Color × Size | GY23: White | GZ23: 21 inch | IE23: http://www.companyname.com/images/1250.main.jpg | IF23: http://www.companyname.com/images/1250.main.jpg | IG23: http://www.companyname.com/images/1250.main.jpg | IO23: 5 | IP23: 2.99 | IQ23: 5.99 | IS23: 9.2 | IT23: 2 | IU23: 3 | IV23: 4 | IY23: 1 Day | IZ23: test1 | JA23: Imported | JB23: GEN STANDARD
B24: 12408 | C24: Example reclaimed Cabinet Solid Wood with 4 Drawers | D24: EXAMPLE-576 | E24: Example_Brand Night Stand with 2 Drawers (White, 24 inch) | DL24: Wood | DQ24: Painted | DR24: Cedar | DS24: Vintage | DT24: Plug Powered | DU24: 110V (included)-240V (included) | DV24: US Plug | DZ24: Yes | EA24: Hardwood | EC24: Block Board (large Core Board) | EG24: Yes | EH24: <3.2 Cubic Feet | EI24: <27 Inches | EJ24: <30 Lbs | EK24: Without Battery | EQ24: Red | GT24: Color × Size | GY24: White | GZ24: 24 inch | IE24: http://www.companyname.com/images/1250.main.jpg | IF24: http://www.companyname.com/images/1250.main.jpg | IG24: http://www.companyname.com/images/1250.main.jpg | IO24: 5 | IP24: 2.99 | IQ24: 5.99 | IS24: 9.2 | IT24: 2 | IU24: 3 | IV24: 4 | IY24: 1 Day | IZ24: test1 | JA24: Imported | JB24: GEN STANDARD
B25: 12408 | C25: Example reclaimed Cabinet Solid Wood with 4 Drawers | D25: EXAMPLE-576 | E25: Example_Brand Night Stand with 2 Drawers (Grey, 21 inch) | DL25: Wood | DQ25: Painted | DR25: Cedar | DS25: Vintage | DT25: Plug Powered | DU25: 110V (included)-240V (included) | DV25: US Plug | DZ25: Yes | EA25: Hardwood | EC25: Block Board (large Core Board) | EG25: Yes | EH25: <3.2 Cubic Feet | EI25: <27 Inches | EJ25: <30 Lbs | EK25: Without Battery | EQ25: Red | GT25: Color × Size | GY25: Grey | GZ25: 21 inch | IE25: http://www.companyname.com/images/1250.main.jpg | IF25: http://www.companyname.com/images/1250.main.jpg | IG25: http://www.companyname.com/images/1250.main.jpg | IO25: 5 | IP25: 2.99 | IQ25: 5.99 | IS25: 9.2 | IT25: 2 | IU25: 3 | IV25: 4 | IY25: 1 Day | IZ25: test1 | JA25: Imported | JB25: GEN STANDARD
B26: 12408 | C26: Example reclaimed Cabinet Solid Wood with 4 Drawers | D26: EXAMPLE-576 | E26: Example_Brand Night Stand with 2 Drawers (Grey, 24 inch) | DL26: Wood | DQ26: Painted | DR26: Cedar | DS26: Vintage | DT26: Plug Powered | DU26: 110V (included)-240V (included) | DV26: US Plug | DZ26: Yes | EA26: Hardwood | EC26: Block Board (large Core Board) | EG26: Yes | EH26: <3.2 Cubic Feet | EI26: <27 Inches | EJ26: <30 Lbs | EK26: Without Battery | EQ26: Red | GT26: Color × Size | GY26: Grey | GZ26: 24 inch | IE26: http://www.companyname.com/images/1250.main.jpg | IF26: http://www.companyname.com/images/1250.main.jpg | IG26: http://www.companyname.com/images/1250.main.jpg | IO26: 5 | IP26: 2.99 | IQ26: 5.99 | IS26: 9.2 | IT26: 2 | IU26: 3 | IV26: 4 | IY26: 1 Day | IZ26: test1 | JA26: Imported | JB26: GEN STANDARD

Sheet Data Definitions
A1: How to complete your template
A2: Group Name | B2: Field Name | C2: Local Label Name | D2: Definition and Use | E2: Accepted Values | F2: Example | G2: Required?
A3: Product Identity - These are attributes that are important to buyers and should be populated for all your items. Some are required to create an offer.
B4: t_0_category | C4: Category | D4: Only supports uploading a single category of goods. Category ID has been preset in the dropdown. | E4: Input an appropriate category. | F4: 13788 | G4: Required
B5: t_0_productname | C5: Product Name | D5: Following MMS guidelines: Maximum of 500 characters, must not contain blank lines or more than two consecutive spaces. | E5: Provide a name for the item including brand, color, fit and size,in 500 characters | F5: Robert Graham Men's Maya Bay Short Sleeve Classic Fit Shirt, Cranberry, X-Large | G5: Required
B6: t_0_contributiongoods | C6: Contribution Goods | D6: The code provided by the platform to providers for marking and managing parent product links, filled in by the merchant. Must be unique within the store. Rows with the same Contribution Goods value will be treated by the system as different child SKUs under the same parent product. Please do not use leading or trailing spaces in SKUs. | E6: This attribute indicates the SKU number as assigned by the contributor | F6: ABC123 | G6: Required
B7: t_0_contributionsku | C7: Contribution SKU | D7: The code provided by the platform to providers for marking and managing sub-product links, filled in by the merchant. Must be unique within the store.Please do not use leading or trailing spaces in SKUs. | E7: This attribute indicates the SKU number as assigned by the contributor | F7: ABC123 | G7: Required
B8: t_0_brand | C8: Brand | D8: If the product requires brand information, please select both Brand and Trademark of that. | E8: Select the brand name of the product https://seller-eu.temu.com/performance/account-health.html?tab=compliance&opType=register | F8: Nike | G8: Optional
B9: t_0_trademark | C9: Trademark | D9: If the product requires brand information, please select both Brand and Trademark of that. Please take care when selecting the Brand and Trademark you want to associate with. | E9: Select the trademark name of the product | F9: Nike | G9: Optional
A10: Product Description - These attributes have an effect on how customers can find your product on the site using browse or search
B11: t_1_productdescription | C11: Product Description | D11: A text description of the product. | E11: Following MMS guidelines: Maximum of 2000 characters, not support the rich text formatting. | F11: Long sleeve v-neck cardigan with a ribbed waistline and pockets with bow detailing | G11: Optional
B12: t_1_bulletpoint | C12: Bullet Point | D12: Brief descriptive text, called out via a bullet point, regarding a specific aspect of the product. These display directly under or next to your product photo, it is useful to put interesting information in these fields. Bullet points will be inserted automatically. | E12: Following MMS guidelines: Maximum of 700 characters, not support the rich text formatting. You can upload one bullet point per cell | F12: Made with nourishing pure aloe vera gel | G12: Optional
B13: t_1_detailimagesurl | C13: Detail Images URL | D13: The URL for detail images of your product. These images will be shown on the detail page when the customer clicks through to see other views associated with the product. For example, you can use this field to show the label information or packaging of your product. Upload additional images with different views to the item, or with some emotional surrounding as additional image. | E13: Obtain URLs from any image hosting website and enter them into the respective cells. i. Aspect ratio: min of 1:3; ii. Width or height: min of 480px; iii. File size: max of 3MB; iv. File types: jpeg, jpg, png | F13: http://www.companyname.com/images/1250.main.jpg | G13: Optional
B14: t_1_detailvideourl | C14: Detail Video URL | D14: The URL for detail video of your product. The detail video will be presented at the top of the product details section. | E14: Obtain URLs from any image hosting website and enter them into the respective cells. i. Aspect ratio: 1:1, 4:3, 16:9 ii. Resolution: min of 720p iii. Duration: max of 180s iv. File size: max of 300MB v. File types: wmv, avi, 3gp, mov, mp4, flv, rmvb, mkv, m4v, x-flv | F14: http://www.companyname.com/videos/1250..mp4 | G14: Optional
A15: Sale Property (At Least One, At Most Two) - These attributes used for product is available in different variations
B16: t_3_variationtheme | C16: Variation Theme | D16: Describes the parameter(s) by which the parent product may vary. The value input for this field should be the same for all the SKUs of the same product. Example: If the product varies by size, input the value Size. If the product varies by color, input the value Color. Terms used for variation themes are created by you the merchant. (e.g. 'quantity' can be any number that you choose). | E16: Select and applicable variation theme. | F16: Color × Size | G16: Required
A17: Variations - These are attributes that are important to buyers and should be populated for the sku of the product
B18: t_5_skuimagesurl | C18: SKU Images URL | D18: The SKU images will be displayed at the top of the product page when the customer clicks through to see other views associated with the product. Different SKU images will form a carousel of the product. For example, you can use this field to show the label information or packaging of your product. Upload additional images with different views to the item, or with some emotional surrounding as additional image. | E18: a. For clothes: i. Aspect ratio: 3:4 ii. Width: min of 1340px iii. Height: min of 1785px iv. File size: max of 3MB v. File types: jpeg, jpg, png b. For other products: i. Aspect ratio: 1:1 ii. Width or height: min of 800px iii. File size: max of 3MB iv. File types: jpeg, jpg, png | F18: http://www.companyname.com/images/1250.main.jpg | G18: Required
B19: t_5_dimensions | C19: Dimensions | D19: Please use imperial units to indicate product dimensions. This can help buyers get a better understanding of the size and specifications of the product. | E19: a. For clothes: i. Aspect ratio: 3:4 ii. Width: min of 1340px iii. Height: min of 1785px iv. File size: max of 3MB v. File types: jpeg, jpg, png b. For other products: i. Aspect ratio: 1:1 ii. Width or height: min of 800px iii. File size: max of 3MB iv. File types: jpeg, jpg, png | F19: http://www.companyname.com/images/1250.dimension.jpg | G19: Optional
B20: t_5_quantity | C20: Quantity | D20: Enter the quantity of the item you are making available for sale. This is your current INVENTORY commitment. Quantity is required for all "child" or stand-alone items. If left blank when first submitting the product information, the item will be displayed as "Out of stock." | E20: Enter the quantity of the item you are making available for sale. This is your current inventory commitment (as a whole number) | F20: 152 | G20: Required
B21: t_5_baseprice_eur | C21: Base Price - EUR | D21: The Base Price should reflect your costs and expected profit. You'll receive sales proceeds based on the Operative Price for each product sold. The final Retail Price is not directly linked to your payment settlement. Base price must be less than list price. | E21: The price range is €0.01-€99999999.99, with a maximum of 2 decimal places, and will be rounded up. | F21: 3.99 | G21: Required
B22: t_5_Recommended retail price_eur | C22: Recommended retail price - EUR | D22: The list price is the suggested or recommended retail price of a product set by the manufacturer. It must be a genuine selling price on the market and in compliance with applicable laws and regulations. If your product is listed for sale in the EU, the product must have been advertised and sold at or above the provided list price by at least one EU retailer. By inputting a list price you are confirming that: - You are not the only seller of the product on the market where the product will be sold (and where a list price comparison will be made); and - You have evidence that the list price you are providing is a genuine price at which the product is generally sold. You must make such evidence available to Temu on request. Base price must be less than list price. | E22: The price range is €0.01-€99999999.99, with a maximum of 2 decimal places, and will be rounded up. | F22: 5.79 | G22: Required
B23: t_5_notavailableforlistprice | C23: Not available for List price | D23: The list price is the suggested or recommended retail price of a product set by the manufacturer. It must be a genuine selling price in the market, complying with applicable laws and regulations. If your product is listed for sale in the EU, the product must have been advertised and sold at the list price provided or above by at least one EU retailer. If your product does not have a list price that meets these criteria, you may set as N/A(Not available). | E23: Select N/A if your product does not have a list price | F23: N/A | G23: Optional
B24: t_5_weight_g | C24: Weight - g | D24: This will be used to indicate the package weight of the SKU and will be used by Temu to estimate logistics costs. Please fill this in accurately. | E24: The weight range is 0.1 g-9,999,999.9 g, with a maximum of 1 decimal place, and will be rounded up | F24: 10.2 | G24: Required
B25: t_5_length_cm | C25: Length - cm | D25: This will be used to indicate the package volune of the SKU and will be used by Temu to estimate logistics costs. Please fill this in accurately. | E25: The length range is 0.1 cm-9,999.9 cm, with a maximum of 1 decimal point, and will be rounded up | F25: 3.1 | G25: Required
B26: t_5_width_cm | C26: Width - cm | D26: This will be used to indicate the package volune of the SKU and will be used by Temu to estimate logistics costs. Please fill this in accurately. | E26: The length range is 0.1 cm-9,999.9 cm, with a maximum of 1 decimal point, and will be rounded up | F26: 2.1 | G26: Required
B27: t_5_height_cm | C27: Height - cm | D27: This will be used to indicate the package volune of the SKU and will be used by Temu to estimate logistics costs. Please fill this in accurately. | E27: The length range is 0.1 cm-9,999.9 cm, with a maximum of 1 decimal point, and will be rounded up | F27: 1.1 | G27: Required
B28: t_5_externalproductidtype | C28: External Product ID Type | D28: The type of standard, unique identifier entered in the Product ID field. This is a required field if Product ID is provided. | E28: The type of standard, unique identifier entered in the Product ID field. This is a required field if Product ID is provided. | F28: UPC | G28: Optional
B29: t_5_externalproductid | C29: External Product ID | D29: A standard, alphanumeric string that uniquely identifies the product. This could be a GCID (16 alphanumeric characters), UPC or EAN. This is a required field if product_id_type is provided. | E29: Provide the corresponding external product id value based on the type that was selected | F29: 714532191586 | G29: Optional
A30: Offer - These attributes are required to make your product buyable for customers on the site
B31: t_6_handlingtime | C31: Handling Time | D31: Indicates the time, in days, between when you receive an order for an item and when you can ship the item. The default production time is one to two business days. Use this field if your production time is greater than two business days. | E31: The same as MMS. Only supports 1, 2 days. | F31: 1 Day | G31: Required
B32: t_6_shippingtemplate | C32: Shipping Template | D32: Sellers can create a set of ship configurations based on business needs and use cases. The ship configurations can be region based and have rules to set SLA and rate for the region. When listing product to create offer, seller needs to select one ship configuration for the product. The ship configuration will be used to retrieve the valid ship options on the website. | E32: Must first finish creating the shipping template in [https://seller-eu.temu.com/shipping-templates-create.html], and all available shipping template names in the store will be displayed here. | F32: "Free Shipping Template", "Default Template" | G32: Required
B33: t_6_fulfillmentchannel | C33: Fulfillment Channel | G33: Required
B34: t_6_itemtaxcode | C34: Item Tax Code | D34: The Item tax code (ITC) matches a product with the correct VAT rate prescribed for the relevant product category. If no ITC is assigned to the product, the default value from “calculation settings” will be applied. | E34: Enter the item tax code supplied to you by temu.com. | F34: GEN STANDARD | G34: Optional
A35: Qualifications - Attributes used to comply with consumer laws in the country or region where the item is sold
B36: t_8_product_guide | C36: Product Guide | E36: Please get the URL of the manual from any image hosting website and fill it into the cell. Product Guide Filing Requirements: a. File size: max of 15MB b. File type: pdf | F36: http://www.companyname.com/guide/1250.pdf | G36: Optional
B37: t_8_Country/Region of Origin | C37: Country/Region of Origin | D37: The Country/Region of Origin of a product is generally the country or region where the product was wholly produced or manufactured. If more than one country or region is involved in the product’s production or manufacture, the Country/Region of Origin is generally where the last "substantial transformation" of the product occurred. | E37: Select the Country/Region of the product | F37: Germany | G37: Required
B38: t_8_Province of Origin | C38: Province of Origin | D38: When the country of origin is Mainland China, the province of origin cannot not be empty. | E38: Select the Province of the product | G38: Required
B39: t_8_Have any products under this goods ID been placed on the EU (or Northern Ireland) market after December 13, 2024? | C39: Have any products under this goods ID been placed on the EU (or Northern Ireland) market after December 13, 2024? | D39: If you select “Yes. Products under this goods ID have been placed on the EU(or Northern Ireland) market after December 13, 2024.” your product must comply with the relevant GPSR requirements，Declare the manufacturer、EU responsible person、 identification code、warning and safety information (if applicable) and upload Compliance images in the Product Compliance page. Otherwise, non-compliant goods will be removed from the EU site and the Northern Ireland region of the UK. If you have not yet submitted the required information, Please submit on the product editing page as soon as possible. You can know more about the GPSR requirements by searching“GPSR filing information and FAQs”on help center-Policy&Operational article page. | G39: Required
B40: t_8_Product Identification | C40: Product Identification | D40: For products placed on the EU (or Northern Ireland) market after December 13, 2024, you shall declare the product identification, otherwise it will affect sales in EU (or Northern Ireland) market. You can declare batch number, serial number, or any other elements that can be used to identify and trace the product as product identification. | G40: Required
...

Sheet Template
A1: Processing Results | E1: Product Identity | T1: Product Description | DS1: Product Detail | KF1: Sale Property (At Least One, At Most Two) | KK1: Size Chart | LO1: Variations | MS1: Offer | MW1: Qualifications
